<mujoco model="upper_body">
    <worldbody>
        <geom name="floor" pos="0 0 -0.5" size="0 0 1" type="plane" material="matplane" rgba="0.8 0.6 0.4 1"/>   
        <light directional="true" diffuse=".8 .8 .8" specular=".2 .2 .2" pos="0 0 5" dir="0 1 -5"/>
        <geom pos="0.00776 0.00282 0.62658" type="mesh" mesh="torso" />
        <body name="shoulder_right_link1" pos="-0.21017 0 0.69947">
            <inertial pos="0.000927262 -0.000754323 0.000586995" quat="0.880142 -0.270778 -0.134381 -0.366022" mass="0.00942681" diaginertia="7.88358e-07 6.71508e-07 6.71379e-07" />
            <joint name="shoulder_right_axis0" pos="0 0 0" axis="0.97437 0 -0.22495" limited="true" range="-1 0.3" />
            <geom type="mesh" mesh="shoulder_right_link1" />
            <body name="shoulder_right_link2" pos="0 0 0">
                <inertial pos="-2.85947e-06 -3.29215e-06 -1.17765e-05" quat="-0.144897 0.75326 -0.229487 0.599116" mass="0.000785157" diaginertia="1.11977e-08 1.11626e-08 1.10533e-08" />
                <joint name="shoulder_right_axis1" pos="0 0 0" axis="0 -1 0" limited="true" range="-1.2 0" />
                <geom type="mesh" mesh="shoulder_right_link2" />
            </body>
        </body>
    </worldbody>
    <tendon>
        <spatial name="T_M0" width="0.0025" rgba="0.55 0.78 0.55 1">
            <site site="vp_front_upper_left"/>
            <site site="vp_front_lower_left"/>
        </spatial>
        <spatial name="T_M1" width="0.0025" rgba="0.55 0.78 0.55 1">
            <site site="vp_back_upper_left"/>
            <site site="vp_back_lower_left"/>
        </spatial>
    </tendon>
    <actuator>
   </actuator>
</mujoco>
